<?xml version="1.0"?>
<robot name="quanser">

<!--'	<link name="quanser_origin"/>'-->

	<link name="bloco">
		<visual>
      			<geometry>
        			<box size="0.24 0.24 0.24"/>
 			</geometry>
			<material name="gray">
				<color rgba="1 0 0 0.7"/>
			</material>
		</visual>
		<collision>
			<geometry>
				<box size="0.24 0.24 0.24"/>
			</geometry>
		</collision>
		<inertial>
			<origin xyz="0.0 0.0 0.0" rpy="0 0 0" />
			<mass value="0.2" />
			<inertia ixx="1.0" ixy="0.0" ixz="0.0" iyy="1.0" iyz="0.0" izz="1.0" />
		</inertial>
	</link>

	<link name="link1">
		<visual>
      			<geometry>
        			<box size="0.343 0.05 0.002"/>
 			</geometry>
			<material name="gray">
				<color rgba="0 1 0 0.7"/>
			</material>
		</visual>
		<collision>
			<geometry>
        			<box size="0.343 0.05 0.002"/>
			</geometry>
		</collision>
		<inertial>
			<origin xyz="0.0 0.0 0.0" rpy="0 0 0" />
			<mass value="0.01" />
			<inertia ixx="1.0" ixy="0.0" ixz="0.0" iyy="1.0" iyz="0.0" izz="1.0" />
		</inertial>
	</link>

	<link name="link2">
		<visual>
      			<geometry>
        			<box size="0.267 0.05 0.002" />        			
 			</geometry>
			<material name="gray">
				<color rgba="0 0 1 0.7"/>
			</material>
		</visual>
		<collision>
			<geometry>
        			<box size="0.267 0.05 0.002" />        			
			</geometry>
		</collision>
		<inertial>
			<origin xyz="0.0 0.0 0.0" rpy="0 0 0" />
			<mass value="0.01" />
			<inertia ixx="1.0" ixy="0.0" ixz="0.0" iyy="1.0" iyz="0.0" izz="1.0" />
		</inertial>
	</link>
	
<!--	<joint name="origem" type="fixed" />
		<origin xyz="0 0 0" rpy="0 0 0" />
		<parent link="quanser_origin" />
		<child link="bloco" />
	</joint>
-->
	<joint name="joint_bloco_link1" type="revolute">
		<origin xyz="0.28 0.00 0.00" rpy="1.57 0 0" />
		<parent link="bloco" />
		<child link="link1" />
		<limit effort="30" velocity="1.0" lower="-1.52" upper="1.52" />
	</joint>

	<joint name="joint_link1_link2" type="revolute">
		<origin xyz="0.28 0.0 0.0" rpy="0 0 0" />
		<parent link="link1" />
		<child link="link2" />
		<limit effort="30" velocity="1.0" lower="-1.52" upper="1.52" />
	</joint>


	<gazebo reference="bloco">
		<material>Gazebo/Gray</material>
	</gazebo>

	<gazebo reference="link1">
		<material>Gazebo/Gray</material>
	</gazebo>

	<gazebo reference="link2">
		<material>Gazebo/Gray</material>
	</gazebo>
</robot>
