<?xml version="1.0"?>
<robot name="quanser">

	<link name="bloco">
		<visual>
      			<geometry>
        			<box size="0.12 0.2 0.24"/>
 			</geometry>
			<material name="black">
				<color rgba="0 0 0 1"/>
			</material>
		</visual>
		<collision>
			<geometry>
				<box size="0.12 0.2 0.24"/>
			</geometry>
		</collision>
		<inertial>
			<origin xyz="0.0 0.0 0.0" rpy="0 0 0" />
			<mass value="0.2" />
			<inertia ixx="0.0" ixy="0.0" ixz="0.0" iyy="0.0" iyz="0.0" izz="0.0" />
		</inertial>
	</link>

	<link name="link1">
		<visual>
      			<geometry>
        			<box size="0.343 0.05 0.002"/>
 			</geometry>
			<material name="black">
				<color rgba="0 0 0 1"/>
			</material>
		</visual>
		<collision>
			<geometry>
        			<box size="0.343 0.05 0.002"/>
			</geometry>
		</collision>
		<inertial>
			<origin xyz="0.0 0.0 0.0" rpy="0 0 0" />
			<mass value="0.01" />
			<inertia ixx="0.0" ixy="0.0" ixz="0.0" iyy="0.0" iyz="0.0" izz="0.0" />
		</inertial>
	</link>

	<link name="link2">
		<visual>
      			<geometry>
        			<box size="0.267 0.05 0.002" />        			
 			</geometry>
			<material name="black">
				<color rgba="0 0 0 1"/>
			</material>
		</visual>
		<collision>
			<geometry>
        			<box size="0.267 0.05 0.002" />        			
			</geometry>
		</collision>
		<inertial>
			<origin xyz="0.0 0.0 0.0" rpy="0 0 0" />
			<mass value="0.01" />
			<inertia ixx="0.0" ixy="0.0" ixz="0.0" iyy="0.0" iyz="0.0" izz="0.0" />
		</inertial>
	</link>
	
	<joint name="joint_bloco_link1" type="revolute">
		<origin xyz="0.23 0.00 0.00" rpy="1.57 0 0" />
		<parent link="bloco" />
		<child link="link1" />
		<limit effort="30" velocity="1.0" lower="-1.57" upper="1.57" />
	</joint>

	<joint name="joint_link1_link2" type="revolute">
		<origin xyz="0.3 0.0 0.0" rpy="0 0 0" />
		<parent link="link1" />
		<child link="link2" />
		<limit effort="30" velocity="1.0" lower="-1.57" upper="1.57" />
	</joint>


	<gazebo reference="bloco">
		<material>Gazebo/Black</material>
	</gazebo>

	<gazebo reference="link1">
		<material>Gazebo/Black</material>
	</gazebo>

	<gazebo reference="link2">
		<material>Gazebo/Black</material>
	</gazebo> 
</robot>
